Workbook

Sheet Graphs
B2: Overall | C2: 1 | D2: 2 | E2: 3 | F2: 4 | G2: 5 | H2: 6 | I2: 7 | T2: Macro F1 Score | W2: SOTA
A3: GPT | B3: =Main!E40 -> 0.95931 | T3: GPT 4.1m | U3: Gemini 2.5 Flash | V3: Gemini 3.1 Pro | W3: Legal BERT
A4: GPT | S4: Zero Shot LLM Fairness | T4: =Main!G52 -> 0.44107 | U4: =Main!G53 -> 0.57518 | V4: =Main!G54 -> 0.63136 | W4: N/A
A5: Gemin | S5: Zero Shot Prompting | T5: =Main!G45 -> 0.53627 | U5: =Main!G50 -> 0.6782 | V5: =Main!G51 -> 0.71753 | W5: N/A
S6: Few Shot Prompting | T6: =Main!G57 -> 0.65973 | U6: =Main!G60 -> 0.7003 | V6: =Main!G61 -> 0.73928 | W6: N/A
A7: Overall Methodology Comparison (Grouped Bar Chart or Summary Table) | S7: Fined Tuned | T7: =Main!G40 -> 0.83037 | U7: =Main!G41 -> 0.80666 | V7: N/A | W7: 0.83
A25: Handling Class Imbalance (Confusion Matrices or Stacked Bar Charts)
A27: Not sure how to
A30: Performance Across Specific Unfair Categories (Radar Chart or Detailed Heatmap)
A32: Check Main Sheet
A35: The Progression of Prompt Engineering (Line Graph)
AA40: 5532 | AB40: =AA40/$AA$43 -> 0.58763544
AA41: 2275 | AB41: =AA41/$AA$43 -> 0.24166136
AA42: 1607 | AB42: =AA42/$AA$43 -> 0.17070321
AA43: =SUM(AA40:AA42) -> 9414 | AB43: =AA43/$AA$43 -> 1

Sheet Main
B1: Name | C1: Tab Name | D1: Category | E1: Precision | F1: Recall | G1: F1 | H1: F1 Micro | I1: Support | J1: TP | K1: FP | L1: FN | M1: TN | N1: Accuracy | O1: invalid_prediction_count | P1: invalid_prediction_rate
E2: B | F2: C | G2: D | H2: E | I2: F | J2: G | K2: H | L2: I | M2: J | N2: K | O2: L | P2: M
B3: GPT4.1m-fine-tunned | C3: GPT4.1m-fine-tunned | D3: All | E3: {=INDIRECT("'"&$C3&"'!"&E$2&MATCH($D3,INDIRECT("'"&$C3&"'!$A:$A"),0))} -> 0.95931 | F3: {=INDIRECT("'"&$C3&"'!"&F$2&MATCH($D3,INDIRECT("'"&$C3&"'!$A:$A"),0))} -> 0.9599 | G3: {=INDIRECT("'"&$C3&"'!"&G$2&MATCH($D3,INDIRECT("'"&$C3&"'!$A:$A"),0))} -> 0.83037 | I3: {=INDIRECT("'"&$C3&"'!"&I$2&MATCH($D3,INDIRECT("'"&$C3&"'!$A:$A"),0))} -> 1607 | N3: {=INDIRECT("'"&$C3&"'!"&N$2&MATCH($D3,INDIRECT("'"&$C3&"'!$A:$A"),0))} -> 0.95644 | O3: {=INDIRECT("'"&$C3&"'!"&O$2&MATCH($D3,INDIRECT("'"&$C3&"'!$A:$A"),0))} -> 0 | P3: {=INDIRECT("'"&$C3&"'!"&P$2&MATCH($D3,INDIRECT("'"&$C3&"'!$A:$A"),0))} -> 0
B4: GPT4.1m-fine-tunned | C4: GPT4.1m-fine-tunned | D4: 0 | E4: {=INDIRECT("'"&$C4&"'!"&E$2&MATCH($D4,INDIRECT("'"&$C4&"'!$A:$A"),0))} -> 0.70455 | F4: {=INDIRECT("'"&$C4&"'!"&F$2&MATCH($D4,INDIRECT("'"&$C4&"'!$A:$A"),0))} -> 0.81579 | G4: {=INDIRECT("'"&$C4&"'!"&G$2&MATCH($D4,INDIRECT("'"&$C4&"'!$A:$A"),0))} -> 0.7561 | I4: {=INDIRECT("'"&$C4&"'!"&I$2&MATCH($D4,INDIRECT("'"&$C4&"'!$A:$A"),0))} -> 38 | J4: {=INDIRECT("'"&$C4&"'!"&J$2&MATCH($D4,INDIRECT("'"&$C4&"'!$A:$A"),0))} -> 31 | K4: {=INDIRECT("'"&$C4&"'!"&K$2&MATCH($D4,INDIRECT("'"&$C4&"'!$A:$A"),0))} -> 13 | L4: {=INDIRECT("'"&$C4&"'!"&L$2&MATCH($D4,INDIRECT("'"&$C4&"'!$A:$A"),0))} -> 7
B5: GPT4.1m-fine-tunned | C5: GPT4.1m-fine-tunned | D5: 1 | E5: {=INDIRECT("'"&$C5&"'!"&E$2&MATCH($D5,INDIRECT("'"&$C5&"'!$A:$A"),0))} -> 0.78378 | F5: {=INDIRECT("'"&$C5&"'!"&F$2&MATCH($D5,INDIRECT("'"&$C5&"'!$A:$A"),0))} -> 0.76316 | G5: {=INDIRECT("'"&$C5&"'!"&G$2&MATCH($D5,INDIRECT("'"&$C5&"'!$A:$A"),0))} -> 0.77333 | I5: {=INDIRECT("'"&$C5&"'!"&I$2&MATCH($D5,INDIRECT("'"&$C5&"'!$A:$A"),0))} -> 38 | J5: {=INDIRECT("'"&$C5&"'!"&J$2&MATCH($D5,INDIRECT("'"&$C5&"'!$A:$A"),0))} -> 29 | K5: {=INDIRECT("'"&$C5&"'!"&K$2&MATCH($D5,INDIRECT("'"&$C5&"'!$A:$A"),0))} -> 8 | L5: {=INDIRECT("'"&$C5&"'!"&L$2&MATCH($D5,INDIRECT("'"&$C5&"'!$A:$A"),0))} -> 9
B6: GPT4.1m-fine-tunned | C6: GPT4.1m-fine-tunned | D6: 2 | E6: {=INDIRECT("'"&$C6&"'!"&E$2&MATCH($D6,INDIRECT("'"&$C6&"'!$A:$A"),0))} -> 0.84375 | F6: {=INDIRECT("'"&$C6&"'!"&F$2&MATCH($D6,INDIRECT("'"&$C6&"'!$A:$A"),0))} -> 0.71053 | G6: {=INDIRECT("'"&$C6&"'!"&G$2&MATCH($D6,INDIRECT("'"&$C6&"'!$A:$A"),0))} -> 0.77143 | I6: {=INDIRECT("'"&$C6&"'!"&I$2&MATCH($D6,INDIRECT("'"&$C6&"'!$A:$A"),0))} -> 38 | J6: {=INDIRECT("'"&$C6&"'!"&J$2&MATCH($D6,INDIRECT("'"&$C6&"'!$A:$A"),0))} -> 27 | K6: {=INDIRECT("'"&$C6&"'!"&K$2&MATCH($D6,INDIRECT("'"&$C6&"'!$A:$A"),0))} -> 5 | L6: {=INDIRECT("'"&$C6&"'!"&L$2&MATCH($D6,INDIRECT("'"&$C6&"'!$A:$A"),0))} -> 11
B7: GPT4.1m-fine-tunned | C7: GPT4.1m-fine-tunned | D7: 3 | E7: {=INDIRECT("'"&$C7&"'!"&E$2&MATCH($D7,INDIRECT("'"&$C7&"'!$A:$A"),0))} -> 0.61905 | F7: {=INDIRECT("'"&$C7&"'!"&F$2&MATCH($D7,INDIRECT("'"&$C7&"'!$A:$A"),0))} -> 1 | G7: {=INDIRECT("'"&$C7&"'!"&G$2&MATCH($D7,INDIRECT("'"&$C7&"'!$A:$A"),0))} -> 0.76471 | I7: {=INDIRECT("'"&$C7&"'!"&I$2&MATCH($D7,INDIRECT("'"&$C7&"'!$A:$A"),0))} -> 13 | J7: {=INDIRECT("'"&$C7&"'!"&J$2&MATCH($D7,INDIRECT("'"&$C7&"'!$A:$A"),0))} -> 13 | K7: {=INDIRECT("'"&$C7&"'!"&K$2&MATCH($D7,INDIRECT("'"&$C7&"'!$A:$A"),0))} -> 8 | L7: {=INDIRECT("'"&$C7&"'!"&L$2&MATCH($D7,INDIRECT("'"&$C7&"'!$A:$A"),0))} -> 0
B8: GPT4.1m-fine-tunned | C8: GPT4.1m-fine-tunned | D8: 4 | E8: {=INDIRECT("'"&$C8&"'!"&E$2&MATCH($D8,INDIRECT("'"&$C8&"'!$A:$A"),0))} -> 0.81818 | F8: {=INDIRECT("'"&$C8&"'!"&F$2&MATCH($D8,INDIRECT("'"&$C8&"'!$A:$A"),0))} -> 0.78261 | G8: {=INDIRECT("'"&$C8&"'!"&G$2&MATCH($D8,INDIRECT("'"&$C8&"'!$A:$A"),0))} -> 0.8 | I8: {=INDIRECT("'"&$C8&"'!"&I$2&MATCH($D8,INDIRECT("'"&$C8&"'!$A:$A"),0))} -> 23 | J8: {=INDIRECT("'"&$C8&"'!"&J$2&MATCH($D8,INDIRECT("'"&$C8&"'!$A:$A"),0))} -> 18 | K8: {=INDIRECT("'"&$C8&"'!"&K$2&MATCH($D8,INDIRECT("'"&$C8&"'!$A:$A"),0))} -> 4 | L8: {=INDIRECT("'"&$C8&"'!"&L$2&MATCH($D8,INDIRECT("'"&$C8&"'!$A:$A"),0))} -> 5
B9: GPT4.1m-fine-tunned | C9: GPT4.1m-fine-tunned | D9: 5 | E9: {=INDIRECT("'"&$C9&"'!"&E$2&MATCH($D9,INDIRECT("'"&$C9&"'!$A:$A"),0))} -> 1 | F9: {=INDIRECT("'"&$C9&"'!"&F$2&MATCH($D9,INDIRECT("'"&$C9&"'!$A:$A"),0))} -> 0.92308 | G9: {=INDIRECT("'"&$C9&"'!"&G$2&MATCH($D9,INDIRECT("'"&$C9&"'!$A:$A"),0))} -> 0.96 | I9: {=INDIRECT("'"&$C9&"'!"&I$2&MATCH($D9,INDIRECT("'"&$C9&"'!$A:$A"),0))} -> 13 | J9: {=INDIRECT("'"&$C9&"'!"&J$2&MATCH($D9,INDIRECT("'"&$C9&"'!$A:$A"),0))} -> 12 | K9: {=INDIRECT("'"&$C9&"'!"&K$2&MATCH($D9,INDIRECT("'"&$C9&"'!$A:$A"),0))} -> 0 | L9: {=INDIRECT("'"&$C9&"'!"&L$2&MATCH($D9,INDIRECT("'"&$C9&"'!$A:$A"),0))} -> 1
B10: GPT4.1m-fine-tunned | C10: GPT4.1m-fine-tunned | D10: 6 | E10: {=INDIRECT("'"&$C10&"'!"&E$2&MATCH($D10,INDIRECT("'"&$C10&"'!$A:$A"),0))} -> 1 | F10: {=INDIRECT("'"&$C10&"'!"&F$2&MATCH($D10,INDIRECT("'"&$C10&"'!$A:$A"),0))} -> 1 | G10: {=INDIRECT("'"&$C10&"'!"&G$2&MATCH($D10,INDIRECT("'"&$C10&"'!$A:$A"),0))} -> 1 | I10: {=INDIRECT("'"&$C10&"'!"&I$2&MATCH($D10,INDIRECT("'"&$C10&"'!$A:$A"),0))} -> 16 | J10: {=INDIRECT("'"&$C10&"'!"&J$2&MATCH($D10,INDIRECT("'"&$C10&"'!$A:$A"),0))} -> 16 | K10: {=INDIRECT("'"&$C10&"'!"&K$2&MATCH($D10,INDIRECT("'"&$C10&"'!$A:$A"),0))} -> 0 | L10: {=INDIRECT("'"&$C10&"'!"&L$2&MATCH($D10,INDIRECT("'"&$C10&"'!$A:$A"),0))} -> 0
B11: GPT4.1m-fine-tunned | C11: GPT4.1m-fine-tunned | D11: 7 | E11: {=INDIRECT("'"&$C11&"'!"&E$2&MATCH($D11,INDIRECT("'"&$C11&"'!$A:$A"),0))} -> 0.54545 | F11: {=INDIRECT("'"&$C11&"'!"&F$2&MATCH($D11,INDIRECT("'"&$C11&"'!$A:$A"),0))} -> 0.85714 | G11: {=INDIRECT("'"&$C11&"'!"&G$2&MATCH($D11,INDIRECT("'"&$C11&"'!$A:$A"),0))} -> 0.66667 | I11: {=INDIRECT("'"&$C11&"'!"&I$2&MATCH($D11,INDIRECT("'"&$C11&"'!$A:$A"),0))} -> 7 | J11: {=INDIRECT("'"&$C11&"'!"&J$2&MATCH($D11,INDIRECT("'"&$C11&"'!$A:$A"),0))} -> 6 | K11: {=INDIRECT("'"&$C11&"'!"&K$2&MATCH($D11,INDIRECT("'"&$C11&"'!$A:$A"),0))} -> 5 | L11: {=INDIRECT("'"&$C11&"'!"&L$2&MATCH($D11,INDIRECT("'"&$C11&"'!$A:$A"),0))} -> 1
B12: GPT4.1m-fine-tunned | C12: GPT4.1m-fine-tunned | D12: 8 | E12: {=INDIRECT("'"&$C12&"'!"&E$2&MATCH($D12,INDIRECT("'"&$C12&"'!$A:$A"),0))} -> 0.98388 | F12: {=INDIRECT("'"&$C12&"'!"&F$2&MATCH($D12,INDIRECT("'"&$C12&"'!$A:$A"),0))} -> 0.9784 | G12: {=INDIRECT("'"&$C12&"'!"&G$2&MATCH($D12,INDIRECT("'"&$C12&"'!$A:$A"),0))} -> 0.98113 | I12: {=INDIRECT("'"&$C12&"'!"&I$2&MATCH($D12,INDIRECT("'"&$C12&"'!$A:$A"),0))} -> 1435 | J12: {=INDIRECT("'"&$C12&"'!"&J$2&MATCH($D12,INDIRECT("'"&$C12&"'!$A:$A"),0))} -> 1404 | K12: {=INDIRECT("'"&$C12&"'!"&K$2&MATCH($D12,INDIRECT("'"&$C12&"'!$A:$A"),0))} -> 23 | L12: {=INDIRECT("'"&$C12&"'!"&L$2&MATCH($D12,INDIRECT("'"&$C12&"'!$A:$A"),0))} -> 31
B13: GPT4.1m-fine-tunned | C13: GPT4.1m-fine-tunned | D13: unfair_binary | E13: {=INDIRECT("'"&$C13&"'!"&E$2&MATCH($D13,INDIRECT("'"&$C13&"'!$A:$A"),0))} -> 0.82778 | F13: {=INDIRECT("'"&$C13&"'!"&F$2&MATCH($D13,INDIRECT("'"&$C13&"'!$A:$A"),0))} -> 0.86628 | G13: {=INDIRECT("'"&$C13&"'!"&G$2&MATCH($D13,INDIRECT("'"&$C13&"'!$A:$A"),0))} -> 0.84659 | J13: {=INDIRECT("'"&$C13&"'!"&J$2&MATCH($D13,INDIRECT("'"&$C13&"'!$A:$A"),0))} -> 149 | K13: {=INDIRECT("'"&$C13&"'!"&K$2&MATCH($D13,INDIRECT("'"&$C13&"'!$A:$A"),0))} -> 31 | L13: {=INDIRECT("'"&$C13&"'!"&L$2&MATCH($D13,INDIRECT("'"&$C13&"'!$A:$A"),0))} -> 23 | M13: {=INDIRECT("'"&$C13&"'!"&M$2&MATCH($D13,INDIRECT("'"&$C13&"'!$A:$A"),0))} -> 1404 | N13: {=INDIRECT("'"&$C13&"'!"&N$2&MATCH($D13,INDIRECT("'"&$C13&"'!$A:$A"),0))} -> 0.9664
B15: Gemini-2.5-flash-fine-tunned | C15: Gemini-2.5-flash-fine-tunned | D15: All | E15: {=INDIRECT("'"&$C15&"'!"&E$2&MATCH($D15,INDIRECT("'"&$C15&"'!$A:$A"),0))} -> 0.94479 | F15: {=INDIRECT("'"&$C15&"'!"&F$2&MATCH($D15,INDIRECT("'"&$C15&"'!$A:$A"),0))} -> 0.95003 | G15: {=INDIRECT("'"&$C15&"'!"&G$2&MATCH($D15,INDIRECT("'"&$C15&"'!$A:$A"),0))} -> 0.80666 | I15: {=INDIRECT("'"&$C15&"'!"&I$2&MATCH($D15,INDIRECT("'"&$C15&"'!$A:$A"),0))} -> 1607 | N15: {=INDIRECT("'"&$C15&"'!"&N$2&MATCH($D15,INDIRECT("'"&$C15&"'!$A:$A"),0))} -> 0.94213 | O15: {=INDIRECT("'"&$C15&"'!"&O$2&MATCH($D15,INDIRECT("'"&$C15&"'!$A:$A"),0))} -> 0 | P15: {=INDIRECT("'"&$C15&"'!"&P$2&MATCH($D15,INDIRECT("'"&$C15&"'!$A:$A"),0))} -> 0
B16: Gemini-2.5-flash-fine-tunned | C16: Gemini-2.5-flash-fine-tunned | D16: 0 | E16: {=INDIRECT("'"&$C16&"'!"&E$2&MATCH($D16,INDIRECT("'"&$C16&"'!$A:$A"),0))} -> 0.625 | F16: {=INDIRECT("'"&$C16&"'!"&F$2&MATCH($D16,INDIRECT("'"&$C16&"'!$A:$A"),0))} -> 0.78947 | G16: {=INDIRECT("'"&$C16&"'!"&G$2&MATCH($D16,INDIRECT("'"&$C16&"'!$A:$A"),0))} -> 0.69767 | I16: {=INDIRECT("'"&$C16&"'!"&I$2&MATCH($D16,INDIRECT("'"&$C16&"'!$A:$A"),0))} -> 38 | J16: {=INDIRECT("'"&$C16&"'!"&J$2&MATCH($D16,INDIRECT("'"&$C16&"'!$A:$A"),0))} -> 30 | K16: {=INDIRECT("'"&$C16&"'!"&K$2&MATCH($D16,INDIRECT("'"&$C16&"'!$A:$A"),0))} -> 18 | L16: {=INDIRECT("'"&$C16&"'!"&L$2&MATCH($D16,INDIRECT("'"&$C16&"'!$A:$A"),0))} -> 8
B17: Gemini-2.5-flash-fine-tunned | C17: Gemini-2.5-flash-fine-tunned | D17: 1 | E17: {=INDIRECT("'"&$C17&"'!"&E$2&MATCH($D17,INDIRECT("'"&$C17&"'!$A:$A"),0))} -> 0.62264 | F17: {=INDIRECT("'"&$C17&"'!"&F$2&MATCH($D17,INDIRECT("'"&$C17&"'!$A:$A"),0))} -> 0.86842 | G17: {=INDIRECT("'"&$C17&"'!"&G$2&MATCH($D17,INDIRECT("'"&$C17&"'!$A:$A"),0))} -> 0.72527 | I17: {=INDIRECT("'"&$C17&"'!"&I$2&MATCH($D17,INDIRECT("'"&$C17&"'!$A:$A"),0))} -> 38 | J17: {=INDIRECT("'"&$C17&"'!"&J$2&MATCH($D17,INDIRECT("'"&$C17&"'!$A:$A"),0))} -> 33 | K17: {=INDIRECT("'"&$C17&"'!"&K$2&MATCH($D17,INDIRECT("'"&$C17&"'!$A:$A"),0))} -> 20 | L17: {=INDIRECT("'"&$C17&"'!"&L$2&MATCH($D17,INDIRECT("'"&$C17&"'!$A:$A"),0))} -> 5
B18: Gemini-2.5-flash-fine-tunned | C18: Gemini-2.5-flash-fine-tunned | D18: 2 | E18: {=INDIRECT("'"&$C18&"'!"&E$2&MATCH($D18,INDIRECT("'"&$C18&"'!$A:$A"),0))} -> 0.64706 | F18: {=INDIRECT("'"&$C18&"'!"&F$2&MATCH($D18,INDIRECT("'"&$C18&"'!$A:$A"),0))} -> 0.86842 | G18: {=INDIRECT("'"&$C18&"'!"&G$2&MATCH($D18,INDIRECT("'"&$C18&"'!$A:$A"),0))} -> 0.74157 | I18: {=INDIRECT("'"&$C18&"'!"&I$2&MATCH($D18,INDIRECT("'"&$C18&"'!$A:$A"),0))} -> 38 | J18: {=INDIRECT("'"&$C18&"'!"&J$2&MATCH($D18,INDIRECT("'"&$C18&"'!$A:$A"),0))} -> 33 | K18: {=INDIRECT("'"&$C18&"'!"&K$2&MATCH($D18,INDIRECT("'"&$C18&"'!$A:$A"),0))} -> 18 | L18: {=INDIRECT("'"&$C18&"'!"&L$2&MATCH($D18,INDIRECT("'"&$C18&"'!$A:$A"),0))} -> 5
B19: Gemini-2.5-flash-fine-tunned | C19: Gemini-2.5-flash-fine-tunned | D19: 3 | E19: {=INDIRECT("'"&$C19&"'!"&E$2&MATCH($D19,INDIRECT("'"&$C19&"'!$A:$A"),0))} -> 0.66667 | F19: {=INDIRECT("'"&$C19&"'!"&F$2&MATCH($D19,INDIRECT("'"&$C19&"'!$A:$A"),0))} -> 0.92308 | G19: {=INDIRECT("'"&$C19&"'!"&G$2&MATCH($D19,INDIRECT("'"&$C19&"'!$A:$A"),0))} -> 0.77419 | I19: {=INDIRECT("'"&$C19&"'!"&I$2&MATCH($D19,INDIRECT("'"&$C19&"'!$A:$A"),0))} -> 13 | J19: {=INDIRECT("'"&$C19&"'!"&J$2&MATCH($D19,INDIRECT("'"&$C19&"'!$A:$A"),0))} -> 12 | K19: {=INDIRECT("'"&$C19&"'!"&K$2&MATCH($D19,INDIRECT("'"&$C19&"'!$A:$A"),0))} -> 6 | L19: {=INDIRECT("'"&$C19&"'!"&L$2&MATCH($D19,INDIRECT("'"&$C19&"'!$A:$A"),0))} -> 1
B20: Gemini-2.5-flash-fine-tunned | C20: Gemini-2.5-flash-fine-tunned | D20: 4 | E20: {=INDIRECT("'"&$C20&"'!"&E$2&MATCH($D20,INDIRECT("'"&$C20&"'!$A:$A"),0))} -> 0.76 | F20: {=INDIRECT("'"&$C20&"'!"&F$2&MATCH($D20,INDIRECT("'"&$C20&"'!$A:$A"),0))} -> 0.82609 | G20: {=INDIRECT("'"&$C20&"'!"&G$2&MATCH($D20,INDIRECT("'"&$C20&"'!$A:$A"),0))} -> 0.79167 | I20: {=INDIRECT("'"&$C20&"'!"&I$2&MATCH($D20,INDIRECT("'"&$C20&"'!$A:$A"),0))} -> 23 | J20: {=INDIRECT("'"&$C20&"'!"&J$2&MATCH($D20,INDIRECT("'"&$C20&"'!$A:$A"),0))} -> 19 | K20: {=INDIRECT("'"&$C20&"'!"&K$2&MATCH($D20,INDIRECT("'"&$C20&"'!$A:$A"),0))} -> 6 | L20: {=INDIRECT("'"&$C20&"'!"&L$2&MATCH($D20,INDIRECT("'"&$C20&"'!$A:$A"),0))} -> 4
B21: Gemini-2.5-flash-fine-tunned | C21: Gemini-2.5-flash-fine-tunned | D21: 5 | E21: {=INDIRECT("'"&$C21&"'!"&E$2&MATCH($D21,INDIRECT("'"&$C21&"'!$A:$A"),0))} -> 0.92308 | F21: {=INDIRECT("'"&$C21&"'!"&F$2&MATCH($D21,INDIRECT("'"&$C21&"'!$A:$A"),0))} -> 0.92308 | G21: {=INDIRECT("'"&$C21&"'!"&G$2&MATCH($D21,INDIRECT("'"&$C21&"'!$A:$A"),0))} -> 0.92308 | I21: {=INDIRECT("'"&$C21&"'!"&I$2&MATCH($D21,INDIRECT("'"&$C21&"'!$A:$A"),0))} -> 13 | J21: {=INDIRECT("'"&$C21&"'!"&J$2&MATCH($D21,INDIRECT("'"&$C21&"'!$A:$A"),0))} -> 12 | K21: {=INDIRECT("'"&$C21&"'!"&K$2&MATCH($D21,INDIRECT("'"&$C21&"'!$A:$A"),0))} -> 1 | L21: {=INDIRECT("'"&$C21&"'!"&L$2&MATCH($D21,INDIRECT("'"&$C21&"'!$A:$A"),0))} -> 1
B22: Gemini-2.5-flash-fine-tunned | C22: Gemini-2.5-flash-fine-tunned | D22: 6 | E22: {=INDIRECT("'"&$C22&"'!"&E$2&MATCH($D22,INDIRECT("'"&$C22&"'!$A:$A"),0))} -> 1 | F22: {=INDIRECT("'"&$C22&"'!"&F$2&MATCH($D22,INDIRECT("'"&$C22&"'!$A:$A"),0))} -> 1 | G22: {=INDIRECT("'"&$C22&"'!"&G$2&MATCH($D22,INDIRECT("'"&$C22&"'!$A:$A"),0))} -> 1 | I22: {=INDIRECT("'"&$C22&"'!"&I$2&MATCH($D22,INDIRECT("'"&$C22&"'!$A:$A"),0))} -> 16 | J22: {=INDIRECT("'"&$C22&"'!"&J$2&MATCH($D22,INDIRECT("'"&$C22&"'!$A:$A"),0))} -> 16 | K22: {=INDIRECT("'"&$C22&"'!"&K$2&MATCH($D22,INDIRECT("'"&$C22&"'!$A:$A"),0))} -> 0 | L22: {=INDIRECT("'"&$C22&"'!"&L$2&MATCH($D22,INDIRECT("'"&$C22&"'!$A:$A"),0))} -> 0
B23: Gemini-2.5-flash-fine-tunned | C23: Gemini-2.5-flash-fine-tunned | D23: 7 | E23: {=INDIRECT("'"&$C23&"'!"&E$2&MATCH($D23,INDIRECT("'"&$C23&"'!$A:$A"),0))} -> 0.5 | F23: {=INDIRECT("'"&$C23&"'!"&F$2&MATCH($D23,INDIRECT("'"&$C23&"'!$A:$A"),0))} -> 0.85714 | G23: {=INDIRECT("'"&$C23&"'!"&G$2&MATCH($D23,INDIRECT("'"&$C23&"'!$A:$A"),0))} -> 0.63158 | I23: {=INDIRECT("'"&$C23&"'!"&I$2&MATCH($D23,INDIRECT("'"&$C23&"'!$A:$A"),0))} -> 7 | J23: {=INDIRECT("'"&$C23&"'!"&J$2&MATCH($D23,INDIRECT("'"&$C23&"'!$A:$A"),0))} -> 6 | K23: {=INDIRECT("'"&$C23&"'!"&K$2&MATCH($D23,INDIRECT("'"&$C23&"'!$A:$A"),0))} -> 6 | L23: {=INDIRECT("'"&$C23&"'!"&L$2&MATCH($D23,INDIRECT("'"&$C23&"'!$A:$A"),0))} -> 1
B24: Gemini-2.5-flash-fine-tunned | C24: Gemini-2.5-flash-fine-tunned | D24: 8 | E24: {=INDIRECT("'"&$C24&"'!"&E$2&MATCH($D24,INDIRECT("'"&$C24&"'!$A:$A"),0))} -> 0.98924 | F24: {=INDIRECT("'"&$C24&"'!"&F$2&MATCH($D24,INDIRECT("'"&$C24&"'!$A:$A"),0))} -> 0.96098 | G24: {=INDIRECT("'"&$C24&"'!"&G$2&MATCH($D24,INDIRECT("'"&$C24&"'!$A:$A"),0))} -> 0.9749 | I24: {=INDIRECT("'"&$C24&"'!"&I$2&MATCH($D24,INDIRECT("'"&$C24&"'!$A:$A"),0))} -> 1435 | J24: {=INDIRECT("'"&$C24&"'!"&J$2&MATCH($D24,INDIRECT("'"&$C24&"'!$A:$A"),0))} -> 1379 | K24: {=INDIRECT("'"&$C24&"'!"&K$2&MATCH($D24,INDIRECT("'"&$C24&"'!$A:$A"),0))} -> 15 | L24: {=INDIRECT("'"&$C24&"'!"&L$2&MATCH($D24,INDIRECT("'"&$C24&"'!$A:$A"),0))} -> 56
B25: Gemini-2.5-flash-fine-tunned | C25: Gemini-2.5-flash-fine-tunned | D25: unfair_binary | E25: {=INDIRECT("'"&$C25&"'!"&E$2&MATCH($D25,INDIRECT("'"&$C25&"'!$A:$A"),0))} -> 0.73709 | F25: {=INDIRECT("'"&$C25&"'!"&F$2&MATCH($D25,INDIRECT("'"&$C25&"'!$A:$A"),0))} -> 0.91279 | G25: {=INDIRECT("'"&$C25&"'!"&G$2&MATCH($D25,INDIRECT("'"&$C25&"'!$A:$A"),0))} -> 0.81558 | J25: {=INDIRECT("'"&$C25&"'!"&J$2&MATCH($D25,INDIRECT("'"&$C25&"'!$A:$A"),0))} -> 157 | K25: {=INDIRECT("'"&$C25&"'!"&K$2&MATCH($D25,INDIRECT("'"&$C25&"'!$A:$A"),0))} -> 56 | L25: {=INDIRECT("'"&$C25&"'!"&L$2&MATCH($D25,INDIRECT("'"&$C25&"'!$A:$A"),0))} -> 15 | M25: {=INDIRECT("'"&$C25&"'!"&M$2&MATCH($D25,INDIRECT("'"&$C25&"'!$A:$A"),0))} -> 1379 | N25: {=INDIRECT("'"&$C25&"'!"&N$2&MATCH($D25,INDIRECT("'"&$C25&"'!$A:$A"),0))} -> 0.95582
B27: Few Shot Gemini 3.1 Pro | C27: FS6-Full-Gemini3.1-pro-25.04.26 | D27: All | E27: {=INDIRECT("'"&$C27&"'!"&E$2&MATCH($D27,INDIRECT("'"&$C27&"'!$A:$A"),0))} -> 0.91983 | F27: {=INDIRECT("'"&$C27&"'!"&F$2&MATCH($D27,INDIRECT("'"&$C27&"'!$A:$A"),0))} -> 0.92721 | G27: {=INDIRECT("'"&$C27&"'!"&G$2&MATCH($D27,INDIRECT("'"&$C27&"'!$A:$A"),0))} -> 0.73928 | I27: {=INDIRECT("'"&$C27&"'!"&I$2&MATCH($D27,INDIRECT("'"&$C27&"'!$A:$A"),0))} -> 1607 | N27: {=INDIRECT("'"&$C27&"'!"&N$2&MATCH($D27,INDIRECT("'"&$C27&"'!$A:$A"),0))} -> 0.9191 | O27: {=INDIRECT("'"&$C27&"'!"&O$2&MATCH($D27,INDIRECT("'"&$C27&"'!$A:$A"),0))} -> 0 | P27: {=INDIRECT("'"&$C27&"'!"&P$2&MATCH($D27,INDIRECT("'"&$C27&"'!$A:$A"),0))} -> 0
B28: Few Shot Gemini 3.1 Pro | C28: FS6-Full-Gemini3.1-pro-25.04.26 | D28: 0 | E28: {=INDIRECT("'"&$C28&"'!"&E$2&MATCH($D28,INDIRECT("'"&$C28&"'!$A:$A"),0))} -> 0.47541 | F28: {=INDIRECT("'"&$C28&"'!"&F$2&MATCH($D28,INDIRECT("'"&$C28&"'!$A:$A"),0))} -> 0.76316 | G28: {=INDIRECT("'"&$C28&"'!"&G$2&MATCH($D28,INDIRECT("'"&$C28&"'!$A:$A"),0))} -> 0.58586 | I28: {=INDIRECT("'"&$C28&"'!"&I$2&MATCH($D28,INDIRECT("'"&$C28&"'!$A:$A"),0))} -> 38 | J28: {=INDIRECT("'"&$C28&"'!"&J$2&MATCH($D28,INDIRECT("'"&$C28&"'!$A:$A"),0))} -> 29 | K28: {=INDIRECT("'"&$C28&"'!"&K$2&MATCH($D28,INDIRECT("'"&$C28&"'!$A:$A"),0))} -> 32 | L28: {=INDIRECT("'"&$C28&"'!"&L$2&MATCH($D28,INDIRECT("'"&$C28&"'!$A:$A"),0))} -> 9 | Q28: Limitation of Liability
B29: Few Shot Gemini 3.1 Pro | C29: FS6-Full-Gemini3.1-pro-25.04.26 | D29: 1 | E29: {=INDIRECT("'"&$C29&"'!"&E$2&MATCH($D29,INDIRECT("'"&$C29&"'!$A:$A"),0))} -> 0.65455 | F29: {=INDIRECT("'"&$C29&"'!"&F$2&MATCH($D29,INDIRECT("'"&$C29&"'!$A:$A"),0))} -> 0.94737 | G29: {=INDIRECT("'"&$C29&"'!"&G$2&MATCH($D29,INDIRECT("'"&$C29&"'!$A:$A"),0))} -> 0.77419 | I29: {=INDIRECT("'"&$C29&"'!"&I$2&MATCH($D29,INDIRECT("'"&$C29&"'!$A:$A"),0))} -> 38 | J29: {=INDIRECT("'"&$C29&"'!"&J$2&MATCH($D29,INDIRECT("'"&$C29&"'!$A:$A"),0))} -> 36 | K29: {=INDIRECT("'"&$C29&"'!"&K$2&MATCH($D29,INDIRECT("'"&$C29&"'!$A:$A"),0))} -> 19 | L29: {=INDIRECT("'"&$C29&"'!"&L$2&MATCH($D29,INDIRECT("'"&$C29&"'!$A:$A"),0))} -> 2 | Q29: Unilateral Termination
B30: Few Shot Gemini 3.1 Pro | C30: FS6-Full-Gemini3.1-pro-25.04.26 | D30: 2 | E30: {=INDIRECT("'"&$C30&"'!"&E$2&MATCH($D30,INDIRECT("'"&$C30&"'!$A:$A"),0))} -> 0.54386 | F30: {=INDIRECT("'"&$C30&"'!"&F$2&MATCH($D30,INDIRECT("'"&$C30&"'!$A:$A"),0))} -> 0.81579 | G30: {=INDIRECT("'"&$C30&"'!"&G$2&MATCH($D30,INDIRECT("'"&$C30&"'!$A:$A"),0))} -> 0.65263 | I30: {=INDIRECT("'"&$C30&"'!"&I$2&MATCH($D30,INDIRECT("'"&$C30&"'!$A:$A"),0))} -> 38 | J30: {=INDIRECT("'"&$C30&"'!"&J$2&MATCH($D30,INDIRECT("'"&$C30&"'!$A:$A"),0))} -> 31 | K30: {=INDIRECT("'"&$C30&"'!"&K$2&MATCH($D30,INDIRECT("'"&$C30&"'!$A:$A"),0))} -> 26 | L30: {=INDIRECT("'"&$C30&"'!"&L$2&MATCH($D30,INDIRECT("'"&$C30&"'!$A:$A"),0))} -> 7 | Q30: Unilateral Change
B31: Few Shot Gemini 3.1 Pro | C31: FS6-Full-Gemini3.1-pro-25.04.26 | D31: 3 | E31: {=INDIRECT("'"&$C31&"'!"&E$2&MATCH($D31,INDIRECT("'"&$C31&"'!$A:$A"),0))} -> 0.54545 | F31: {=INDIRECT("'"&$C31&"'!"&F$2&MATCH($D31,INDIRECT("'"&$C31&"'!$A:$A"),0))} -> 0.92308 | G31: {=INDIRECT("'"&$C31&"'!"&G$2&MATCH($D31,INDIRECT("'"&$C31&"'!$A:$A"),0))} -> 0.68571 | I31: {=INDIRECT("'"&$C31&"'!"&I$2&MATCH($D31,INDIRECT("'"&$C31&"'!$A:$A"),0))} -> 13 | J31: {=INDIRECT("'"&$C31&"'!"&J$2&MATCH($D31,INDIRECT("'"&$C31&"'!$A:$A"),0))} -> 12 | K31: {=INDIRECT("'"&$C31&"'!"&K$2&MATCH($D31,INDIRECT("'"&$C31&"'!$A:$A"),0))} -> 10 | L31: {=INDIRECT("'"&$C31&"'!"&L$2&MATCH($D31,INDIRECT("'"&$C31&"'!$A:$A"),0))} -> 1 | Q31: Content Removal
B32: Few Shot Gemini 3.1 Pro | C32: FS6-Full-Gemini3.1-pro-25.04.26 | D32: 4 | E32: {=INDIRECT("'"&$C32&"'!"&E$2&MATCH($D32,INDIRECT("'"&$C32&"'!$A:$A"),0))} -> 0.61765 | F32: {=INDIRECT("'"&$C32&"'!"&F$2&MATCH($D32,INDIRECT("'"&$C32&"'!$A:$A"),0))} -> 0.91304 | G32: {=INDIRECT("'"&$C32&"'!"&G$2&MATCH($D32,INDIRECT("'"&$C32&"'!$A:$A"),0))} -> 0.73684 | I32: {=INDIRECT("'"&$C32&"'!"&I$2&MATCH($D32,INDIRECT("'"&$C32&"'!$A:$A"),0))} -> 23 | J32: {=INDIRECT("'"&$C32&"'!"&J$2&MATCH($D32,INDIRECT("'"&$C32&"'!$A:$A"),0))} -> 21 | K32: {=INDIRECT("'"&$C32&"'!"&K$2&MATCH($D32,INDIRECT("'"&$C32&"'!$A:$A"),0))} -> 13 | L32: {=INDIRECT("'"&$C32&"'!"&L$2&MATCH($D32,INDIRECT("'"&$C32&"'!$A:$A"),0))} -> 2 | Q32: Contract by Using
B33: Few Shot Gemini 3.1 Pro | C33: FS6-Full-Gemini3.1-pro-25.04.26 | D33: 5 | E33: {=INDIRECT("'"&$C33&"'!"&E$2&MATCH($D33,INDIRECT("'"&$C33&"'!$A:$A"),0))} -> 0.85714 | F33: {=INDIRECT("'"&$C33&"'!"&F$2&MATCH($D33,INDIRECT("'"&$C33&"'!$A:$A"),0))} -> 0.92308 | G33: {=INDIRECT("'"&$C33&"'!"&G$2&MATCH($D33,INDIRECT("'"&$C33&"'!$A:$A"),0))} -> 0.88889 | I33: {=INDIRECT("'"&$C33&"'!"&I$2&MATCH($D33,INDIRECT("'"&$C33&"'!$A:$A"),0))} -> 13 | J33: {=INDIRECT("'"&$C33&"'!"&J$2&MATCH($D33,INDIRECT("'"&$C33&"'!$A:$A"),0))} -> 12 | K33: {=INDIRECT("'"&$C33&"'!"&K$2&MATCH($D33,INDIRECT("'"&$C33&"'!$A:$A"),0))} -> 2 | L33: {=INDIRECT("'"&$C33&"'!"&L$2&MATCH($D33,INDIRECT("'"&$C33&"'!$A:$A"),0))} -> 1 | Q33: Choice of Law
B34: Few Shot Gemini 3.1 Pro | C34: FS6-Full-Gemini3.1-pro-25.04.26 | D34: 6 | E34: {=INDIRECT("'"&$C34&"'!"&E$2&MATCH($D34,INDIRECT("'"&$C34&"'!$A:$A"),0))} -> 0.84211 | F34: {=INDIRECT("'"&$C34&"'!"&F$2&MATCH($D34,INDIRECT("'"&$C34&"'!$A:$A"),0))} -> 1 | G34: {=INDIRECT("'"&$C34&"'!"&G$2&MATCH($D34,INDIRECT("'"&$C34&"'!$A:$A"),0))} -> 0.91429 | I34: {=INDIRECT("'"&$C34&"'!"&I$2&MATCH($D34,INDIRECT("'"&$C34&"'!$A:$A"),0))} -> 16 | J34: {=INDIRECT("'"&$C34&"'!"&J$2&MATCH($D34,INDIRECT("'"&$C34&"'!$A:$A"),0))} -> 16 | K34: {=INDIRECT("'"&$C34&"'!"&K$2&MATCH($D34,INDIRECT("'"&$C34&"'!$A:$A"),0))} -> 3 | L34: {=INDIRECT("'"&$C34&"'!"&L$2&MATCH($D34,INDIRECT("'"&$C34&"'!$A:$A"),0))} -> 0 | Q34: Jurisdiction
B35: Few Shot Gemini 3.1 Pro | C35: FS6-Full-Gemini3.1-pro-25.04.26 | D35: 7 | E35: {=INDIRECT("'"&$C35&"'!"&E$2&MATCH($D35,INDIRECT("'"&$C35&"'!$A:$A"),0))} -> 0.33333 | F35: {=INDIRECT("'"&$C35&"'!"&F$2&MATCH($D35,INDIRECT("'"&$C35&"'!$A:$A"),0))} -> 0.71429 | G35: {=INDIRECT("'"&$C35&"'!"&G$2&MATCH($D35,INDIRECT("'"&$C35&"'!$A:$A"),0))} -> 0.45455 | I35: {=INDIRECT("'"&$C35&"'!"&I$2&MATCH($D35,INDIRECT("'"&$C35&"'!$A:$A"),0))} -> 7 | J35: {=INDIRECT("'"&$C35&"'!"&J$2&MATCH($D35,INDIRECT("'"&$C35&"'!$A:$A"),0))} -> 5 | K35: {=INDIRECT("'"&$C35&"'!"&K$2&MATCH($D35,INDIRECT("'"&$C35&"'!$A:$A"),0))} -> 10 | L35: {=INDIRECT("'"&$C35&"'!"&L$2&MATCH($D35,INDIRECT("'"&$C35&"'!$A:$A"),0))} -> 2 | Q35: Arbitration
B36: Few Shot Gemini 3.1 Pro | C36: FS6-Full-Gemini3.1-pro-25.04.26 | D36: 8 | E36: {=INDIRECT("'"&$C36&"'!"&E$2&MATCH($D36,INDIRECT("'"&$C36&"'!$A:$A"),0))} -> 0.98821 | F36: {=INDIRECT("'"&$C36&"'!"&F$2&MATCH($D36,INDIRECT("'"&$C36&"'!$A:$A"),0))} -> 0.93449 | G36: {=INDIRECT("'"&$C36&"'!"&G$2&MATCH($D36,INDIRECT("'"&$C36&"'!$A:$A"),0))} -> 0.9606 | I36: {=INDIRECT("'"&$C36&"'!"&I$2&MATCH($D36,INDIRECT("'"&$C36&"'!$A:$A"),0))} -> 1435 | J36: {=INDIRECT("'"&$C36&"'!"&J$2&MATCH($D36,INDIRECT("'"&$C36&"'!$A:$A"),0))} -> 1341 | K36: {=INDIRECT("'"&$C36&"'!"&K$2&MATCH($D36,INDIRECT("'"&$C36&"'!$A:$A"),0))} -> 16 | L36: {=INDIRECT("'"&$C36&"'!"&L$2&MATCH($D36,INDIRECT("'"&$C36&"'!$A:$A"),0))} -> 94 | Q36: Fair
B37: Few Shot Gemini 3.1 Pro | C37: FS6-Full-Gemini3.1-pro-25.04.26 | D37: unfair_binary | E37: {=INDIRECT("'"&$C37&"'!"&E$2&MATCH($D37,INDIRECT("'"&$C37&"'!$A:$A"),0))} -> 0.624 | F37: {=INDIRECT("'"&$C37&"'!"&F$2&MATCH($D37,INDIRECT("'"&$C37&"'!$A:$A"),0))} -> 0.90698 | G37: {=INDIRECT("'"&$C37&"'!"&G$2&MATCH($D37,INDIRECT("'"&$C37&"'!$A:$A"),0))} -> 0.73934 | J37: {=INDIRECT("'"&$C37&"'!"&J$2&MATCH($D37,INDIRECT("'"&$C37&"'!$A:$A"),0))} -> 156 | K37: {=INDIRECT("'"&$C37&"'!"&K$2&MATCH($D37,INDIRECT("'"&$C37&"'!$A:$A"),0))} -> 94 | L37: {=INDIRECT("'"&$C37&"'!"&L$2&MATCH($D37,INDIRECT("'"&$C37&"'!$A:$A"),0))} -> 16 | M37: {=INDIRECT("'"&$C37&"'!"&M$2&MATCH($D37,INDIRECT("'"&$C37&"'!$A:$A"),0))} -> 1341 | N37: {=INDIRECT("'"&$C37&"'!"&N$2&MATCH($D37,INDIRECT("'"&$C37&"'!$A:$A"),0))} -> 0.93155
B40: Fine Tunned GPT 4.1m | C40: GPT4.1m-fine-tunned | D40: All | E40: {=INDIRECT("'"&$C40&"'!"&E$2&MATCH($D40,INDIRECT("'"&$C40&"'!$A:$A"),0))} -> 0.95931 | F40: {=INDIRECT("'"&$C40&"'!"&F$2&MATCH($D40,INDIRECT("'"&$C40&"'!$A:$A"),0))} -> 0.9599 | G40: {=INDIRECT("'"&$C40&"'!"&G$2&MATCH($D40,INDIRECT("'"&$C40&"'!$A:$A"),0))} -> 0.83037 | H40: {=INDIRECT("'"&$C40&"'!"&H$2&MATCH($D40,INDIRECT("'"&$C40&"'!$A:$A"),0))} -> 0.95961 | I40: {=INDIRECT("'"&$C40&"'!"&I$2&MATCH($D40,INDIRECT("'"&$C40&"'!$A:$A"),0))} -> 1607 | N40: {=INDIRECT("'"&$C40&"'!"&N$2&MATCH($D40,INDIRECT("'"&$C40&"'!$A:$A"),0))} -> 0.95644 | O40: {=INDIRECT("'"&$C40&"'!"&O$2&MATCH($D40,INDIRECT("'"&$C40&"'!$A:$A"),0))} -> 0 | P40: {=INDIRECT("'"&$C40&"'!"&P$2&MATCH($D40,INDIRECT("'"&$C40&"'!$A:$A"),0))} -> 0
B41: Fine Tunned Gemini-2.5-flash | C41: Gemini-2.5-flash-fine-tunned | D41: All | E41: {=INDIRECT("'"&$C41&"'!"&E$2&MATCH($D41,INDIRECT("'"&$C41&"'!$A:$A"),0))} -> 0.94479 | F41: {=INDIRECT("'"&$C41&"'!"&F$2&MATCH($D41,INDIRECT("'"&$C41&"'!$A:$A"),0))} -> 0.95003 | G41: {=INDIRECT("'"&$C41&"'!"&G$2&MATCH($D41,INDIRECT("'"&$C41&"'!$A:$A"),0))} -> 0.80666 | H41: {=INDIRECT("'"&$C41&"'!"&H$2&MATCH($D41,INDIRECT("'"&$C41&"'!$A:$A"),0))} -> 0.9474 | I41: {=INDIRECT("'"&$C41&"'!"&I$2&MATCH($D41,INDIRECT("'"&$C41&"'!$A:$A"),0))} -> 1607 | N41: {=INDIRECT("'"&$C41&"'!"&N$2&MATCH($D41,INDIRECT("'"&$C41&"'!$A:$A"),0))} -> 0.94213 | O41: {=INDIRECT("'"&$C41&"'!"&O$2&MATCH($D41,INDIRECT("'"&$C41&"'!$A:$A"),0))} -> 0 | P41: {=INDIRECT("'"&$C41&"'!"&P$2&MATCH($D41,INDIRECT("'"&$C41&"'!$A:$A"),0))} -> 0
B42: V1 Zero Shot 4.1m | C42: ZS1-Full-4.1m-21.03.26 | D42: All | E42: {=INDIRECT("'"&$C42&"'!"&E$2&MATCH($D42,INDIRECT("'"&$C42&"'!$A:$A"),0))} -> 0.6477 | F42: {=INDIRECT("'"&$C42&"'!"&F$2&MATCH($D42,INDIRECT("'"&$C42&"'!$A:$A"),0))} -> 0.66009 | G42: {=INDIRECT("'"&$C42&"'!"&G$2&MATCH($D42,INDIRECT("'"&$C42&"'!$A:$A"),0))} -> 0.45805 | H42: {=INDIRECT("'"&$C42&"'!"&H$2&MATCH($D42,INDIRECT("'"&$C42&"'!$A:$A"),0))} -> 0.65383 | I42: {=INDIRECT("'"&$C42&"'!"&I$2&MATCH($D42,INDIRECT("'"&$C42&"'!$A:$A"),0))} -> 1607 | N42: {=INDIRECT("'"&$C42&"'!"&N$2&MATCH($D42,INDIRECT("'"&$C42&"'!$A:$A"),0))} -> 0.64717 | O42: {=INDIRECT("'"&$C42&"'!"&O$2&MATCH($D42,INDIRECT("'"&$C42&"'!$A:$A"),0))} -> 0 | P42: {=INDIRECT("'"&$C42&"'!"&P$2&MATCH($D42,INDIRECT("'"&$C42&"'!$A:$A"),0))} -> 0
B43: V2 Zero Shot 4.1m | C43: ZS2-Full-4.1m-07.04.26 | D43: All | E43: {=INDIRECT("'"&$C43&"'!"&E$2&MATCH($D43,INDIRECT("'"&$C43&"'!$A:$A"),0))} -> 0.63702 | F43: {=INDIRECT("'"&$C43&"'!"&F$2&MATCH($D43,INDIRECT("'"&$C43&"'!$A:$A"),0))} -> 0.65392 | G43: {=INDIRECT("'"&$C43&"'!"&G$2&MATCH($D43,INDIRECT("'"&$C43&"'!$A:$A"),0))} -> 0.43696 | H43: {=INDIRECT("'"&$C43&"'!"&H$2&MATCH($D43,INDIRECT("'"&$C43&"'!$A:$A"),0))} -> 0.64536 | I43: {=INDIRECT("'"&$C43&"'!"&I$2&MATCH($D43,INDIRECT("'"&$C43&"'!$A:$A"),0))} -> 1607 | N43: {=INDIRECT("'"&$C43&"'!"&N$2&MATCH($D43,INDIRECT("'"&$C43&"'!$A:$A"),0))} -> 0.63783 | O43: {=INDIRECT("'"&$C43&"'!"&O$2&MATCH($D43,INDIRECT("'"&$C43&"'!$A:$A"),0))} -> 0 | P43: {=INDIRECT("'"&$C43&"'!"&P$2&MATCH($D43,INDIRECT("'"&$C43&"'!$A:$A"),0))} -> 0
B44: V3 Zero Shot 5.4n | C44: ZS3-Full-5.4n-14.04.26 | D44: All | E44: {=INDIRECT("'"&$C44&"'!"&E$2&MATCH($D44,INDIRECT("'"&$C44&"'!$A:$A"),0))} -> 0.76951 | F44: {=INDIRECT("'"&$C44&"'!"&F$2&MATCH($D44,INDIRECT("'"&$C44&"'!$A:$A"),0))} -> 0.77236 | G44: {=INDIRECT("'"&$C44&"'!"&G$2&MATCH($D44,INDIRECT("'"&$C44&"'!$A:$A"),0))} -> 0.53727 | H44: {=INDIRECT("'"&$C44&"'!"&H$2&MATCH($D44,INDIRECT("'"&$C44&"'!$A:$A"),0))} -> 0.77094 | I44: {=INDIRECT("'"&$C44&"'!"&I$2&MATCH($D44,INDIRECT("'"&$C44&"'!$A:$A"),0))} -> 1607 | N44: {=INDIRECT("'"&$C44&"'!"&N$2&MATCH($D44,INDIRECT("'"&$C44&"'!$A:$A"),0))} -> 0.7654 | O44: {=INDIRECT("'"&$C44&"'!"&O$2&MATCH($D44,INDIRECT("'"&$C44&"'!$A:$A"),0))} -> 0 | P44: {=INDIRECT("'"&$C44&"'!"&P$2&MATCH($D44,INDIRECT("'"&$C44&"'!$A:$A"),0))} -> 0
...

Sheet Prompts
A1: ZS1 | B1: ZS2 | C1: ZS3 | D1: ZS4 | E1: ZS5 | F1: ZS6 | G1: ZS7 | H1: FS1 (ZS1) | I1: FS3 (ZS1) | J1: FS4 (ZS3)
A2: ## ROLE | B2: ## ROLE | C2: ## ROLE | D2: ## ROLE | E2: ## ROLE | F2: ## ROLE | G2: ## ROLE | H2: ## ROLE | I2: # ROLE | J2: ## ROLE
A3: You are a legal expert specializing in European Consumer Law, specifically Directive 93/13/EEC. Your task is to analyze Terms of Service (TOS) clauses for "significant imbalances" between the rights and obligations of the parties. | B3: You are a legal expert specializing in European Consumer Law, specifically Directive 93/13/EEC. Your task is to analyze Terms of Service (TOS) clauses for "significant imbalances" between the rights and obligations of the parties. | C3: You are a legal expert specializing in European Consumer Law, specifically Directive (EU) 93/13/ECC . Your task is to analyze Terms of Service (TOS) clauses for "significant imbalances" between the rights and obligations of the parties. | D3: You are a legal expert specializing in European Consumer Law, with a focus on Directive (EU) 2019/2161 . Your primary objective is to evaluate whether Terms of Service (TOS) clauses create a "significant imbalance" between the rights of the service provider (provider) and the obligations of the consumer. | E3: You are a legal expert specializing in European Consumer Law, specifically Directive (EU) 93/13/ECC . Your task is to analyze Terms of Service (TOS) clauses for "significant imbalances" between the rights and obligations of the parties. | F3: You are a legal expert specializing in European Consumer Law, specifically Directive (EU) 93/13/ECC . Your task is to analyze Terms of Service (TOS) clauses for "significant imbalances" between the rights and obligations of the parties. | G3: You are a legal expert specializing in European Consumer Law, specifically Directive (EU) 93/13/ECC . Your task is to analyze Terms of Service (TOS) clauses for "significant imbalances" between the rights and obligations of the parties. | H3: You are a legal expert specializing in European Consumer Law, specifically Directive 93/13/EEC. Your task is to analyze Terms of Service (TOS) clauses for "significant imbalances" between the rights and obligations of the parties. | I3: You are a legal expert specializing in European Consumer Law, specifically Directive 93/13/EEC. Your task is to analyze Terms of Service (TOS) clauses for "significant imbalances" between the rights and obligations of the parties. | J3: You are a legal expert specializing in European Consumer Law, specifically Directive (EU) 93/13/ECC . Your task is to analyze Terms of Service (TOS) clauses for "significant imbalances" between the rights and obligations of the parties.
A5: ## Task: | B5: ## Task: | C5: ## Task: | D5: ## Task: | E5: ## Task: | F5: ## Task: | G5: ## Task: | H5: ## Task: | I5: ## Task: | J5: ## Task:
A6: Analyze the provided Terms of Service (TOS) clause: | B6: Analyze the provided Terms of Service (TOS) clause: | C6: Analyze the provided Terms of Service (TOS) clause: | D6: Analyze the provided Terms of Service (TOS) clause to determine if it maintains a fair equilibrium or is unfair: | E6: Analyze the provided Terms of Service (TOS) clause: | F6: Analyze the provided Terms of Service (TOS) clause: | G6: Analyze the provided Terms of Service (TOS) clause: | H6: Analyze the provided Terms of Service (TOS) clause: | I6: Analyze the provided Terms of Service (TOS) clause: | J6: Analyze the provided Terms of Service (TOS) clause:
A7: - If the clause is balanced and legally sound, label it **[8]**. | B7: - If the clause is balanced and legally sound, label it **[8]**. | C7: - If the clause is balanced and legally sound, label it **[8]**. | D7: - If the clause is unfair, label ALL applicable categories of unfairness from **[0-7]**. | E7: - If the clause is balanced and legally sound, label it **[8]**. | F7: - If the clause is unfair, identify ALL applicable categories from **[0-7]**. | G7: - If the clause is unfair, identify ALL applicable categories from **[0-7]**. | H7: - If the clause is balanced and legally sound, label it **[8]**. | I7: - If the clause is balanced and legally sound, label it **[8]**. | J7: - If the clause is balanced and legally sound, label it **[8]**.
A8: - If the clause is unfair, identify ALL applicable categories from **[0-7]**. | B8: - If the clause is unfair, identify ALL applicable categories from **[0-7]**. | C8: - If the clause is unfair, identify ALL applicable categories from **[0-7]**. | D8: - If the clause is fair, balanced and preserves the consumer's legal standing and contains no categories of unfairness 0-7, label it **[8]**. | E8: - If the clause is unfair, identify ALL applicable categories from **[0-7]**. | F8: - If the clause is fair, label it **[8]**. | G8: - If the clause is balanced, fair and legally sound, label it **[8]**. | H8: - If the clause is unfair, identify ALL applicable categories from **[0-7]**. | I8: - If the clause is unfair, identify ALL applicable categories from **[0-7]**. | J8: - If the clause is unfair, identify ALL applicable categories from **[0-7]**.
A9: - **Important**: If any category from 0-7 applies, do NOT include [8] in the label. | B9: - **Important**: If any category from 0-7 applies, do NOT include [8] in the label. | C9: - **Important**: If any category from 0-7 applies, do NOT include [8] in the label. | E9: - **Important**: If any category from 0-7 applies, do NOT include [8] in the label. | F9: - **Important**: If any category from 0-7 applies, do NOT include [8] in the label. | G9: - **Important**: If any category from 0-7 applies, do NOT include [8] in the label. | H9: - **Important**: If any category from 0-7 applies, do NOT include [8] in the label. | I9: - **Important**: If any category from 0-7 applies, do NOT include [8] in the label. | J9: - **Important**: If any category from 0-7 applies, do NOT include [8] in the label.
A11: ## LEGAL CATEGORIES & CRITERIA | B11: -------------------------------------------------------------------------------------------------------------------------------------------------------------------------- | C11: ## LEGAL CATEGORIES & CRITERIA | D11: ## FAIRNESS VS. UNFAIRNESS CRITERIA The following is a list of categories with the detail of what is considered Unfair and Fair. | E11: ## LEGAL CATEGORIES & CRITERIA | F11: ## LEGAL CATEGORIES & CRITERIA | G11: ## LEGAL CATEGORIES & CRITERIA | H11: ## LEGAL CATEGORIES & CRITERIA | I11: ## LEGAL CATEGORIES & CRITERIA | J11: ## LEGAL CATEGORIES & CRITERIA
A12: ### **0-Limitation of Liability:** Covers clauses excluding or restricting a seller's legal liability for non-performance or injury, which is unfair when it creates a significant imbalance by stripping consumers of compensation rights for death or gross negligence, but remains fair if it is transparent, proportional, and explicitly protects mandatory statutory rights. | C12: ### **0-Limitation of Liability:** Covers clauses excluding or restricting a seller's legal liability for non-performance or injury, which is unfair when it creates a significant imbalance by stripping consumers of compensation rights for death or gross negligence, but remains fair if it is transparent, proportional, and explicitly protects mandatory statutory rights. Do not assign [0] for warranty language (for example, "as is" or "no warranty") or third-party resource disclaimers unless the clause also expressly excludes or caps the provider's liability for user damages, losses, or compensation. | D12: ### **0. Limitation of Liability** Unfair: Excludes or restricts provider liability for non-performance, personal injury, or gross negligence. Fair: Clauses that are transparent, proportional, and explicitly protect the consumer's mandatory statutory rights. | E12: ### **0. Limitation of Liability** Unfair: Excludes or restricts provider liability for non-performance, personal injury, or gross negligence. Fair: Clauses that are transparent, proportional, and explicitly protect the consumer's mandatory statutory rights. | F12: ### **0-Limitation of Liability** - Definition: Provider liability to user is limited - Unfair: Excludes or restricts provider liability for non-performance, personal injury, death, or gross negligence when it creates a significant imbalance by stripping consumers of compensation rights. - Fair: Clauses that are transparent, proportional, and explicitly protect the consumer's mandatory statutory rights. - Note: Do not assign [0] for warranty language (for example, "as is" or "no warranty") or third-party resource disclaimers unless the clause also expressly excludes or caps the provider's liability for user damages, losses, or compensation. | G12: ### **0.Limitation of Liability** - Definition: Provider liability to user is limited - Unfair: Excludes or restricts provider liability for non-performance, personal injury, death, or gross negligence when it creates a significant imbalance by stripping consumers of compensation rights. - Fair: Clauses that are transparent, proportional, and explicitly protect the consumer's mandatory statutory rights. - Note: Do not assign [0] for warranty language (for example, "as is" or "no warranty") or third-party resource disclaimers unless the clause also expressly excludes or caps the provider's liability for user damages, losses, or compensation. | H12: ### **0-Limitation of Liability:** Covers clauses excluding or restricting a seller's legal liability for non-performance or injury, which is unfair when it creates a significant imbalance by stripping consumers of compensation rights for death or gross negligence, but remains fair if it is transparent, proportional, and explicitly protects mandatory statutory rights. | I12: ### **0-Limitation of Liability:** Covers clauses excluding or restricting a seller's legal liability for non-performance or injury, which is unfair when it creates a significant imbalance by stripping consumers of compensation rights for death or gross negligence, but remains fair if it is transparent, proportional, and explicitly protects mandatory statutory rights. Do not assign [0] for warranty language (for example, "as is" or "no warranty") or third-party resource disclaimers unless the clause also expressly excludes or caps the provider's liability for user damages, losses, or compensation. | J12: ### **0-Limitation of Liability:** Covers clauses excluding or restricting a seller's legal liability for non-performance or injury, which is unfair when it creates a significant imbalance by stripping consumers of compensation rights for death or gross negligence, but remains fair if it is transparent, proportional, and explicitly protects mandatory statutory rights. Do not assign [0] for warranty language (for example, "as is" or "no warranty") or third-party resource disclaimers unless the clause also expressly excludes or caps the provider's liability for user damages, losses, or compensation.
B13: ## LEGAL CATEGORIES & DEFINITIONS
A14: ### **1-Unilateral Termination:** Involves terms allowing a seller to dissolve the contract at will, which is considered unfair when it lacks reasonable notice or reciprocal rights for the consumer, but can be fair if the contract specifies objective grounds for termination and provides a sufficient notice period. | B14: ### **0-Limitation of Liability:** | C14: ### **1-Unilateral Termination:** Involves terms allowing a seller to dissolve the contract at will, which is considered unfair when it lacks reasonable notice or reciprocal rights for the consumer, but can be fair if the contract specifies objective grounds for termination and provides a sufficient notice period. Clauses that let the provider terminate or restrict access unilaterally are generally [1], even when tied to alleged misuse or policy violations, unless balanced safeguards are explicit. | D14: ### **1. Unilateral Termination** Definition: Terms allowing the provider to dissolve the contract at will. Unfair: Allowing the provider to dissolve the contract "at will" or without reasonable notice or reciprocal rights for the consumer. Fair: Specifying objective grounds for termination and providing a sufficient notice period for the consumer to react. | E14: ### **1. Unilateral Termination** Definition: Terms allowing the provider to dissolve the contract at will. Unfair: Allowing the provider to dissolve the contract "at will" or without reasonable notice or reciprocal rights for the consumer. Fair: Specifying objective grounds for termination and providing a sufficient notice period for the consumer to react. | F14: ### **1-Unilateral Termination** Definition: Terms allowing the provider to dissolve the contract at will. Unfair: Termination with no notice or insufficient notice or where reciprocal rights are not provided for the consumer, even if the user has violated the agreement. Fair: Specifying objective grounds for termination and providing a sufficient notice period. | G14: ### **1.Unilateral Termination** Definition: Terms allowing the provider to dissolve the contract at will. Unfair: Termination with no notice or insufficient notice or where reciprocal rights are not provided for the consumer, even if the user has violated the agreement. Fair: Specifying objective grounds for termination and providing a sufficient notice period. | H14: ### **1-Unilateral Termination:** Involves terms allowing a seller to dissolve the contract at will, which is considered unfair when it lacks reasonable notice or reciprocal rights for the consumer, but can be fair if the contract specifies objective grounds for termination and provides a sufficient notice period. | I14: ### **1-Unilateral Termination:** Involves terms allowing a seller to dissolve the contract at will, which is considered unfair when it lacks reasonable notice or reciprocal rights for the consumer, but can be fair if the contract specifies objective grounds for termination and provides a sufficient notice period. Clauses that let the provider terminate or restrict access unilaterally are generally [1], even when tied to alleged misuse or policy violations, unless balanced safeguards are explicit. | J14: ### **1-Unilateral Termination:** Involves terms allowing a seller to dissolve the contract at will, which is considered unfair when it lacks reasonable notice or reciprocal rights for the consumer, but can be fair if the contract specifies objective grounds for termination and provides a sufficient notice period. Clauses that let the provider terminate or restrict access unilaterally are generally [1], even when tied to alleged misuse or policy violations, unless balanced safeguards are explicit.
B15: **Definition**: In the context of a consumer service contract, a **Limitation of Liability** clause is a legal provision that seeks to restrict the amount and types of compensation (damages) a consumer can recover from a service provider in the event of a breach of contract, negligence, or other legal failures. While some limitations are standard, they become "unfair" when they create a significant imbalance in the rights and obligations of the parties to the detriment of the consumer.
A16: ### **2-Unilateral Change:** Identifies provisions enabling the seller to alter contract terms or prices without consent, which is unfair if it lacks a valid, pre-specified reason, but is considered fair if the seller provides advance notice, a valid justification, and the right for the consumer to terminate the contract immediately without penalty. | C16: ### **2-Unilateral Change:** Identifies provisions enabling the seller to alter contract terms or prices without consent, which is unfair if it lacks a valid, pre-specified reason, but is considered fair if the seller provides advance notice, a valid justification, and the right for the consumer to terminate the contract immediately without penalty. Notice alone does not automatically make a unilateral-change clause [8] in this dataset. | D16: ### **2. Unilateral Change** Unfair: Altering terms or prices without a valid, pre-specified reason or the consumer's consent. Fair: Providing advance notice, valid justification, and the right for the consumer to terminate the contract immediately without penalty. | E16: ### **2. Unilateral Change** Unfair: Altering terms or prices without a valid, pre-specified reason or the consumer's consent. Fair: Providing advance notice, valid justification, and the right for the consumer to terminate the contract immediately without penalty. | F16: ### **2-Unilateral Change** Unfair: Altering terms or prices without a valid, pre-specified reason or the consumer's consent. Fair: Providing advance notice, valid justification, and the right for the consumer to terminate the contract immediately without penalty. | G16: ### **2.Unilateral Change** Unfair: Altering terms or prices without a valid, pre-specified reason or the consumer's consent. Fair: Providing advance notice, valid justification, and the right for the consumer to terminate the contract immediately without penalty. | H16: ### **2-Unilateral Change:** Identifies provisions enabling the seller to alter contract terms or prices without consent, which is unfair if it lacks a valid, pre-specified reason, but is considered fair if the seller provides advance notice, a valid justification, and the right for the consumer to terminate the contract immediately without penalty. | I16: ### **2-Unilateral Change:** Identifies provisions enabling the seller to alter contract terms or prices without consent, which is unfair if it lacks a valid, pre-specified reason, but is considered fair if the seller provides advance notice, a valid justification, and the right for the consumer to terminate the contract immediately without penalty. Notice alone does not automatically make a unilateral-change clause [8] in this dataset. | J16: ### **2-Unilateral Change:** Identifies provisions enabling the seller to alter contract terms or prices without consent, which is unfair if it lacks a valid, pre-specified reason, but is considered fair if the seller provides advance notice, a valid justification, and the right for the consumer to terminate the contract immediately without penalty. Notice alone does not automatically make a unilateral-change clause [8] in this dataset.
B17: **Characteristics**:
A18: ### **3-Content Removal:** Identifies clauses that grant the provider the right to delete, hide, or restrict access to content uploaded by the user. Such terms are classified as unfair when they allow for arbitrary removal without a specified valid reason or notice, as this creates a significant imbalance in the rights of the parties. To be considered fair, the term must be transparent and specify objective grounds for removal, ensuring the consumer is provided with a clear legal rationale for the provider's actions and accompanied by a notification and appeal process. | B18: - **Broad and Blanket Exclusions**: The clause attempts to exclude liability for any loss or damage "howsoever arising," effectively stripping the consumer of any legal recourse regardless of the provider's level of fault. | C18: ### **3-Content Removal:** Identifies clauses that grant the provider the right to delete, hide, or restrict access to content uploaded by the user. Such terms are classified as unfair when they allow for arbitrary removal without a specified valid reason or notice, as this creates a significant imbalance in the rights of the parties. To be considered fair, the term must be transparent and specify objective grounds for removal, ensuring the consumer is provided with a clear legal rationale for the provider's actions and accompanied by a notification and appeal process. | D18: ### **3. Content Removal** Unfair: Granting the provider arbitrary rights to delete or hide user content without a clear reason or notice. Fair: Specifying objective grounds for removal and offering a transparent notification and appeal process. | E18: ### **3. Content Removal** Unfair: Granting the provider arbitrary rights to delete or hide user content without a clear reason or notice. Fair: Specifying objective grounds for removal and offering a transparent notification and appeal process. | F18: ### **3-Content Removal** Unfair: Granting the provider arbitrary rights to delete or hide user content without a clear reason or notice. Fair: Specifying objective grounds for removal and offering a transparent notification and appeal process. | G18: ### **3.Content Removal** Unfair: Granting the provider arbitrary rights to delete or hide user content without a clear reason or notice. Fair: Specifying objective grounds for removal and offering a transparent notification and appeal process. | H18: ### **3-Content Removal:** Identifies clauses that grant the provider the right to delete, hide, or restrict access to content uploaded by the user. Such terms are classified as unfair when they allow for arbitrary removal without a specified valid reason or notice, as this creates a significant imbalance in the rights of the parties. To be considered fair, the term must be transparent and specify objective grounds for removal, ensuring the consumer is provided with a clear legal rationale for the provider's actions and accompanied by a notification and appeal process. | I18: ### **3-Content Removal:** Identifies clauses that grant the provider the right to delete, hide, or restrict access to content uploaded by the user. Such terms are classified as unfair when they allow for arbitrary removal without a specified valid reason or notice, as this creates a significant imbalance in the rights of the parties. To be considered fair, the term must be transparent and specify objective grounds for removal, ensuring the consumer is provided with a clear legal rationale for the provider's actions and accompanied by a notification and appeal process. | J18: ### **3-Content Removal:** Identifies clauses that grant the provider the right to delete, hide, or restrict access to content uploaded by the user. Such terms are classified as unfair when they allow for arbitrary removal without a specified valid reason or notice, as this creates a significant imbalance in the rights of the parties. To be considered fair, the term must be transparent and specify objective grounds for removal, ensuring the consumer is provided with a clear legal rationale for the provider's actions and accompanied by a notification and appeal process.
B19: - **Arbitrary or Insignificant Liability Caps**: The provider limits their total financial responsibility to an incredibly low or arbitrary sum (such as $100 or the price of a single order) that does not reflect the actual harm a consumer might suffer.
A20: ### **4-Contract by Using:** Identifies 'browse-wrap' provisions where the mere use is deemed acceptance of terms, which is unfair under Directive 93/13/EEC as it creates a significant imbalance by binding consumers without informed consent or a genuine opportunity to review the obligations, but it becomes fair when acceptance is conditioned on a clear, affirmative action—like a 'click-wrap' agreement—performed after the consumer has been presented with the terms in a transparent manner. | B20: - **Exclusion of Foreseeable Indirect Losses**: The terms bar consumers from seeking compensation for "consequential," "indirect," or "incidental" damages, such as the loss of data, personal reputation, or goodwill, even when these losses are a direct result of the provider's failure. | C20: ### **4-Contract by Using:** Identifies 'browse-wrap' provisions where the mere use is deemed acceptance of terms, which is unfair under Directive 93/13/EEC as it creates a significant imbalance by binding consumers without informed consent or a genuine opportunity to review the obligations, but it becomes fair when acceptance is conditioned on a clear, affirmative action—like a 'click-wrap' agreement—performed after the consumer has been presented with the terms in a transparent manner. If a clause gives a clear right to reject changes by stopping use or terminating without penalty, prefer [8] over [4]. | D20: ### **4. Contract by Using** Unfair: "Browse-wrap" agreements where mere use is deemed acceptance, binding consumers without informed consent. Fair: "Click-wrap" agreements where acceptance is an affirmative action taken after terms are clearly presented. | E20: ### **4. Contract by Using** Unfair: "Browse-wrap" agreements where mere use is deemed acceptance, binding consumers without informed consent. Fair: "Click-wrap" agreements where acceptance is an affirmative action taken after terms are clearly presented. | F20: ### **4-Contract by Using** Unfair: "Browse-wrap" agreements where mere use is deemed acceptance, binding consumers without informed consent. Fair: "Click-wrap" agreements where acceptance is an affirmative action taken after terms are clearly presented. | G20: ### **4-Contract by Using:** Identifies 'browse-wrap' provisions where the mere use is deemed acceptance of terms, which is unfair under Directive 93/13/EEC as it creates a significant imbalance by binding consumers without informed consent or a genuine opportunity to review the obligations, but it becomes fair when acceptance is conditioned on a clear, affirmative action—like a 'click-wrap' agreement—performed after the consumer has been presented with the terms in a transparent manner. | H20: ### **4-Contract by Using:** Identifies 'browse-wrap' provisions where the mere use is deemed acceptance of terms, which is unfair under Directive 93/13/EEC as it creates a significant imbalance by binding consumers without informed consent or a genuine opportunity to review the obligations, but it becomes fair when acceptance is conditioned on a clear, affirmative action—like a 'click-wrap' agreement—performed after the consumer has been presented with the terms in a transparent manner. | I20: ### **4-Contract by Using:** Identifies 'browse-wrap' provisions where the mere use is deemed acceptance of terms, which is unfair under Directive 93/13/EEC as it creates a significant imbalance by binding consumers without informed consent or a genuine opportunity to review the obligations, but it becomes fair when acceptance is conditioned on a clear, affirmative action—like a 'click-wrap' agreement—performed after the consumer has been presented with the terms in a transparent manner. If a clause gives a clear right to reject changes by stopping use or terminating without penalty, prefer [8] over [4]. | J20: ### **4-Contract by Using:** Identifies 'browse-wrap' provisions where the mere use is deemed acceptance of terms, which is unfair under Directive 93/13/EEC as it creates a significant imbalance by binding consumers without informed consent or a genuine opportunity to review the obligations, but it becomes fair when acceptance is conditioned on a clear, affirmative action—like a 'click-wrap' agreement—performed after the consumer has been presented with the terms in a transparent manner. If a clause gives a clear right to reject changes by stopping use or terminating without penalty, prefer [8] over [4].
B21: - **Disclaiming Responsibility for Third Parties**: The clause absolves the service provider of any liability for the conduct, errors, or omissions of third-party partners, advertisers, or other users, even if the provider facilitated those interactions.
A22: ### **5-Choice of Law:** Designates the legal system governing the contract, which is unfair if it selects a foreign law to deprive consumers of the mandatory protections of their home country, but is fair if it explicitly preserves the consumer's right to their local mandatory legal safeguards. | B22: - **No Accountability for Service Reliability**: The provider claims no responsibility for service interruptions, technical errors, inaccuracies, or the complete unavailability of the service, regardless of the cause or duration. | C22: ### **5-Choice of Law:** Designates the legal system governing the contract, which is unfair if it selects a foreign law to deprive consumers of the mandatory protections of their home country, but is fair if it explicitly preserves the consumer's right to their local mandatory legal safeguards. | D22: ### **5. Choice of Law** Unfair: Selecting a foreign legal system specifically to deprive consumers of their home country’s mandatory protections. Fair: Explicitly preserving the consumer’s right to rely on their local mandatory legal safeguards. | E22: ### **5. Choice of Law** Unfair: Selecting a foreign legal system specifically to deprive consumers of their home country’s mandatory protections. Fair: Explicitly preserving the consumer’s right to rely on their local mandatory legal safeguards. | F22: ### **5-Choice of Law** Unfair: Selecting a foreign legal system specifically to deprive consumers of their home country’s mandatory protections. Fair: Explicitly preserving the consumer’s right to rely on their local mandatory legal safeguards. | G22: ### **5-Choice of Law:** Designates the legal system governing the contract, which is unfair if it selects a foreign law to deprive consumers of the mandatory protections of their home country, but is fair if it explicitly preserves the consumer's right to their local mandatory legal safeguards. | H22: ### **5-Choice of Law:** Designates the legal system governing the contract, which is unfair if it selects a foreign law to deprive consumers of the mandatory protections of their home country, but is fair if it explicitly preserves the consumer's right to their local mandatory legal safeguards. | I22: ### **5-Choice of Law:** Designates the legal system governing the contract, which is unfair if it selects a foreign law to deprive consumers of the mandatory protections of their home country, but is fair if it explicitly preserves the consumer's right to their local mandatory legal safeguards. | J22: ### **5-Choice of Law:** Designates the legal system governing the contract, which is unfair if it selects a foreign law to deprive consumers of the mandatory protections of their home country, but is fair if it explicitly preserves the consumer's right to their local mandatory legal safeguards.
B23: - **Absolute Waiver of Refund Rights**: The terms state that the consumer is not entitled to a refund for any reason, including instances where the account is closed involuntarily or the service is not provided as promised.
